2024-03-13 18:15:40,684 INFO    MainThread:69562 [wandb_setup.py:_flush():76] Current SDK version is 0.16.2
2024-03-13 18:15:40,684 INFO    MainThread:69562 [wandb_setup.py:_flush():76] Configure stats pid to 69562
2024-03-13 18:15:40,684 INFO    MainThread:69562 [wandb_setup.py:_flush():76] Loading settings from /home/tho/.config/wandb/settings
2024-03-13 18:15:40,684 INFO    MainThread:69562 [wandb_setup.py:_flush():76] Loading settings from /home/tho/SCRIMP2/wandb/settings
2024-03-13 18:15:40,684 INFO    MainThread:69562 [wandb_setup.py:_flush():76] Loading settings from environment variables: {}
2024-03-13 18:15:40,685 INFO    MainThread:69562 [wandb_setup.py:_flush():76] Applying setup settings: {'_disable_service': False}
2024-03-13 18:15:40,685 INFO    MainThread:69562 [wandb_setup.py:_flush():76] Inferring run settings from compute environment: {'program_relpath': 'driver.py', 'program_abspath': '/home/tho/SCRIMP2/driver.py', 'program': 'driver.py'}
2024-03-13 18:15:40,685 INFO    MainThread:69562 [wandb_init.py:_log_setup():526] Logging user logs to /home/tho/SCRIMP2/wandb/run-20240313_181540-y8j16gdh/logs/debug.log
2024-03-13 18:15:40,685 INFO    MainThread:69562 [wandb_init.py:_log_setup():527] Logging internal logs to /home/tho/SCRIMP2/wandb/run-20240313_181540-y8j16gdh/logs/debug-internal.log
2024-03-13 18:15:40,685 INFO    MainThread:69562 [wandb_init.py:init():566] calling init triggers
2024-03-13 18:15:40,685 INFO    MainThread:69562 [wandb_init.py:init():574] wandb.init called with sweep_config: {}
config: {'N_AGENTS': 8, 'N_ACTIONS': 5, 'EPISODE_LEN': 256, 'FOV_SIZE': 3, 'WORLD_SIZE': (10, 40), 'OBSTACLE_PROB': (0.0, 0.5), 'ACTION_COST': -0.3, 'IDLE_COST': -0.3, 'GOAL_REWARD': 0.0, 'COLLISION_COST': -2, 'BLOCKING_COST': -1, 'ONLINE_FACTOR': 10, 'lr': 1e-05, 'GAMMA': 0.95, 'LAM': 0.95, 'CLIPRANGE': 0.2, 'MAX_GRAD_NORM': 10, 'ENTROPY_COEF': 0.01, 'IN_VALUE_COEF': 0.08, 'EX_VALUE_COEF': 0.08, 'POLICY_COEF': 10, 'VALID_COEF': 0.5, 'BLOCK_COEF': 0.5, 'N_EPOCHS': 10, 'N_ENVS': 16, 'N_MAX_STEPS': 30000000.0, 'N_STEPS': 1024, 'MINIBATCH_SIZE': 1024, 'DEMONSTRATION_PROB': 0.1, 'NET_SIZE': 512, 'NUM_CHANNEL': 8, 'GOAL_REPR_SIZE': 12, 'VECTOR_LEN': 7, 'N_POSITION': 1024, 'D_MODEL': 512, 'D_HIDDEN': 1024, 'N_LAYERS': 1, 'N_HEAD': 8, 'D_K': 32, 'D_V': 32, 'DIST_FACTOR': 0.1, 'K': 3, 'CAPACITY': 80, 'ADD_THRESHOLD': 3, 'N_ADD_INTRINSIC': 1000000.0, 'SURROGATE1': 0.2, 'SURROGATE2': 1, 'SEED': 1234, 'USE_GPU_LOCAL': False, 'USE_GPU_GLOBAL': False, 'NUM_GPU': 0, 'RETRAIN': False, 'WANDB': True, 'TENSORBOARD': False, 'TXT_WRITER': True, 'ENTITY': 'jianxiongtho', 'TIME': '13-03-241815', 'EXPERIMENT_PROJECT': 'MAPF', 'EXPERIMENT_NAME': 'SCRIMP', 'EXPERIMENT_NOTE': '', 'SAVE_INTERVAL': 500000.0, 'BEST_INTERVAL': 0, 'GIF_INTERVAL': 1000000.0, 'EVAL_INTERVAL': 16384, 'EVAL_EPISODES': 1, 'RECORD_BEST': False, 'MODEL_PATH': './models/MAPF/SCRIMP13-03-241815', 'GIFS_PATH': './gifs/MAPF/SCRIMP13-03-241815', 'SUMMARY_PATH': './summaries/MAPF/SCRIMP13-03-241815', 'TXT_NAME': 'alg.txt'}
2024-03-13 18:15:40,685 INFO    MainThread:69562 [wandb_init.py:init():616] starting backend
2024-03-13 18:15:40,685 INFO    MainThread:69562 [wandb_init.py:init():620] setting up manager
2024-03-13 18:15:40,692 INFO    MainThread:69562 [backend.py:_multiprocessing_setup():107] multiprocessing start_methods=fork,spawn,forkserver, using: spawn
2024-03-13 18:15:40,693 INFO    MainThread:69562 [wandb_init.py:init():628] backend started and connected
2024-03-13 18:15:40,701 INFO    MainThread:69562 [wandb_init.py:init():720] updated telemetry
2024-03-13 18:15:40,713 INFO    MainThread:69562 [wandb_init.py:init():753] communicating run to backend with 90.0 second timeout
2024-03-13 18:17:10,752 ERROR   MainThread:69562 [wandb_init.py:init():779] encountered error: Run initialization has timed out after 90.0 sec. 
Please refer to the documentation for additional information: https://docs.wandb.ai/guides/track/tracking-faq#initstarterror-error-communicating-with-wandb-process-
2024-03-13 18:17:12,762 ERROR   MainThread:69562 [wandb_init.py:init():1194] Run initialization has timed out after 90.0 sec. 
Please refer to the documentation for additional information: https://docs.wandb.ai/guides/track/tracking-faq#initstarterror-error-communicating-with-wandb-process-
Traceback (most recent call last):
  File "/home/tho/anaconda3/envs/scrimp/lib/python3.7/site-packages/wandb/sdk/wandb_init.py", line 1176, in init
    run = wi.init()
  File "/home/tho/anaconda3/envs/scrimp/lib/python3.7/site-packages/wandb/sdk/wandb_init.py", line 785, in init
    raise error
wandb.errors.CommError: Run initialization has timed out after 90.0 sec. 
Please refer to the documentation for additional information: https://docs.wandb.ai/guides/track/tracking-faq#initstarterror-error-communicating-with-wandb-process-
2024-03-13 18:17:39,285 INFO    Thread-2  :69562 [retry.py:__call__():172] Retry attempt failed:
Traceback (most recent call last):
  File "/home/tho/anaconda3/envs/scrimp/lib/python3.7/site-packages/urllib3/connection.py", line 207, in _new_conn
    socket_options=self.socket_options,
  File "/home/tho/anaconda3/envs/scrimp/lib/python3.7/site-packages/urllib3/util/connection.py", line 60, in create_connection
    for res in socket.getaddrinfo(host, port, family, socket.SOCK_STREAM):
  File "/home/tho/anaconda3/envs/scrimp/lib/python3.7/socket.py", line 752, in getaddrinfo
    for res in _socket.getaddrinfo(host, port, family, type, proto, flags):
socket.gaierror: [Errno -3] Temporary failure in name resolution

The above exception was the direct cause of the following exception:

Traceback (most recent call last):
  File "/home/tho/anaconda3/envs/scrimp/lib/python3.7/site-packages/urllib3/connectionpool.py", line 803, in urlopen
    **response_kw,
  File "/home/tho/anaconda3/envs/scrimp/lib/python3.7/site-packages/urllib3/connectionpool.py", line 492, in _make_request
    raise new_e
  File "/home/tho/anaconda3/envs/scrimp/lib/python3.7/site-packages/urllib3/connectionpool.py", line 468, in _make_request
    self._validate_conn(conn)
  File "/home/tho/anaconda3/envs/scrimp/lib/python3.7/site-packages/urllib3/connectionpool.py", line 1097, in _validate_conn
    conn.connect()
  File "/home/tho/anaconda3/envs/scrimp/lib/python3.7/site-packages/urllib3/connection.py", line 611, in connect
    self.sock = sock = self._new_conn()
  File "/home/tho/anaconda3/envs/scrimp/lib/python3.7/site-packages/urllib3/connection.py", line 210, in _new_conn
    raise NameResolutionError(self.host, self, e) from e
urllib3.exceptions.NameResolutionError: <urllib3.connection.HTTPSConnection object at 0x7a6ea07f4e10>: Failed to resolve 'api.wandb.ai' ([Errno -3] Temporary failure in name resolution)

The above exception was the direct cause of the following exception:

Traceback (most recent call last):
  File "/home/tho/anaconda3/envs/scrimp/lib/python3.7/site-packages/requests/adapters.py", line 497, in send
    chunked=chunked,
  File "/home/tho/anaconda3/envs/scrimp/lib/python3.7/site-packages/urllib3/connectionpool.py", line 846, in urlopen
    method, url, error=new_e, _pool=self, _stacktrace=sys.exc_info()[2]
  File "/home/tho/anaconda3/envs/scrimp/lib/python3.7/site-packages/urllib3/util/retry.py", line 515, in increment
    raise MaxRetryError(_pool, url, reason) from reason  # type: ignore[arg-type]
urllib3.exceptions.MaxRetryError: HTTPSConnectionPool(host='api.wandb.ai', port=443): Max retries exceeded with url: /graphql (Caused by NameResolutionError("<urllib3.connection.HTTPSConnection object at 0x7a6ea07f4e10>: Failed to resolve 'api.wandb.ai' ([Errno -3] Temporary failure in name resolution)"))

During handling of the above exception, another exception occurred:

Traceback (most recent call last):
  File "/home/tho/anaconda3/envs/scrimp/lib/python3.7/site-packages/wandb/sdk/lib/retry.py", line 131, in __call__
    result = self._call_fn(*args, **kwargs)
  File "/home/tho/anaconda3/envs/scrimp/lib/python3.7/site-packages/wandb/sdk/internal/internal_api.py", line 369, in execute
    return self.client.execute(*args, **kwargs)  # type: ignore
  File "/home/tho/anaconda3/envs/scrimp/lib/python3.7/site-packages/wandb/vendor/gql-0.2.0/wandb_gql/client.py", line 52, in execute
    result = self._get_result(document, *args, **kwargs)
  File "/home/tho/anaconda3/envs/scrimp/lib/python3.7/site-packages/wandb/vendor/gql-0.2.0/wandb_gql/client.py", line 60, in _get_result
    return self.transport.execute(document, *args, **kwargs)
  File "/home/tho/anaconda3/envs/scrimp/lib/python3.7/site-packages/wandb/sdk/lib/gql_request.py", line 58, in execute
    request = self.session.post(self.url, **post_args)
  File "/home/tho/anaconda3/envs/scrimp/lib/python3.7/site-packages/requests/sessions.py", line 637, in post
    return self.request("POST", url, data=data, json=json, **kwargs)
  File "/home/tho/anaconda3/envs/scrimp/lib/python3.7/site-packages/requests/sessions.py", line 589, in request
    resp = self.send(prep, **send_kwargs)
  File "/home/tho/anaconda3/envs/scrimp/lib/python3.7/site-packages/requests/sessions.py", line 703, in send
    r = adapter.send(request, **kwargs)
  File "/home/tho/anaconda3/envs/scrimp/lib/python3.7/site-packages/requests/adapters.py", line 519, in send
    raise ConnectionError(e, request=request)
requests.exceptions.ConnectionError: HTTPSConnectionPool(host='api.wandb.ai', port=443): Max retries exceeded with url: /graphql (Caused by NameResolutionError("<urllib3.connection.HTTPSConnection object at 0x7a6ea07f4e10>: Failed to resolve 'api.wandb.ai' ([Errno -3] Temporary failure in name resolution)"))
2024-03-13 18:17:45,990 WARNING MsgRouterThr:69562 [router.py:message_loop():77] message_loop has been closed
