2024-03-07 01:00:08,087 INFO    StreamThr :21404 [internal.py:wandb_internal():89] W&B internal server running at pid: 21404, started at: 2024-03-07 01:00:08.086439
2024-03-07 01:00:08,090 DEBUG   HandlerThread:21404 [handler.py:handle_request():146] handle_request: status
2024-03-07 01:00:08,110 INFO    WriterThread:21404 [datastore.py:open_for_write():87] open: /home/tho/SCRIMP/wandb/run-20240307_010008-8w7nwr8q/run-8w7nwr8q.wandb
2024-03-07 01:00:08,110 DEBUG   SenderThread:21404 [sender.py:send():382] send: header
2024-03-07 01:00:08,140 DEBUG   SenderThread:21404 [sender.py:send():382] send: run
2024-03-07 01:00:08,165 INFO    SenderThread:21404 [sender.py:_maybe_setup_resume():764] checking resume status for yutong/MAPF/8w7nwr8q
2024-03-07 01:00:08,991 ERROR   SenderThread:21404 [internal_api.py:execute():373] 404 response executing GraphQL.
2024-03-07 01:00:08,991 ERROR   SenderThread:21404 [internal_api.py:execute():374] {"errors":[{"message":"project not found","path":["upsertBucket"]}],"data":{"upsertBucket":null}}
2024-03-07 01:00:08,992 ERROR   SenderThread:21404 [sender.py:send_run():987] It appears that you do not have permission to access the requested resource. Please reach out to the project owner to grant you access. If you have the correct permissions, verify that there are no issues with your networking setup.(Error 404: Not Found)
Traceback (most recent call last):
  File "/home/tho/anaconda3/envs/scrimp/lib/python3.7/site-packages/wandb/sdk/lib/retry.py", line 131, in __call__
    result = self._call_fn(*args, **kwargs)
  File "/home/tho/anaconda3/envs/scrimp/lib/python3.7/site-packages/wandb/sdk/internal/internal_api.py", line 369, in execute
    return self.client.execute(*args, **kwargs)  # type: ignore
  File "/home/tho/anaconda3/envs/scrimp/lib/python3.7/site-packages/wandb/vendor/gql-0.2.0/wandb_gql/client.py", line 52, in execute
    result = self._get_result(document, *args, **kwargs)
  File "/home/tho/anaconda3/envs/scrimp/lib/python3.7/site-packages/wandb/vendor/gql-0.2.0/wandb_gql/client.py", line 60, in _get_result
    return self.transport.execute(document, *args, **kwargs)
  File "/home/tho/anaconda3/envs/scrimp/lib/python3.7/site-packages/wandb/sdk/lib/gql_request.py", line 59, in execute
    request.raise_for_status()
  File "/home/tho/anaconda3/envs/scrimp/lib/python3.7/site-packages/requests/models.py", line 1021, in raise_for_status
    raise HTTPError(http_error_msg, response=self)
requests.exceptions.HTTPError: 404 Client Error: Not Found for url: https://api.wandb.ai/graphql

During handling of the above exception, another exception occurred:

Traceback (most recent call last):
  File "/home/tho/anaconda3/envs/scrimp/lib/python3.7/site-packages/wandb/sdk/internal/sender.py", line 985, in send_run
    self._init_run(run, config_value_dict)
  File "/home/tho/anaconda3/envs/scrimp/lib/python3.7/site-packages/wandb/sdk/internal/sender.py", line 1041, in _init_run
    commit=run.git.commit or None,
  File "/home/tho/anaconda3/envs/scrimp/lib/python3.7/site-packages/wandb/apis/normalize.py", line 73, in wrapper
    raise err
  File "/home/tho/anaconda3/envs/scrimp/lib/python3.7/site-packages/wandb/apis/normalize.py", line 41, in wrapper
    return func(*args, **kwargs)
  File "/home/tho/anaconda3/envs/scrimp/lib/python3.7/site-packages/wandb/sdk/internal/internal_api.py", line 2220, in upsert_run
    **kwargs,
  File "/home/tho/anaconda3/envs/scrimp/lib/python3.7/site-packages/wandb/sdk/internal/internal_api.py", line 344, in gql
    **kwargs,
  File "/home/tho/anaconda3/envs/scrimp/lib/python3.7/site-packages/wandb/sdk/lib/retry.py", line 147, in __call__
    retry_timedelta_triggered = check_retry_fn(e)
  File "/home/tho/anaconda3/envs/scrimp/lib/python3.7/site-packages/wandb/util.py", line 965, in check_retry_fn
    return fallback_retry_fn(e)
  File "/home/tho/anaconda3/envs/scrimp/lib/python3.7/site-packages/wandb/util.py", line 908, in no_retry_auth
    "It appears that you do not have permission to access the requested resource. "
wandb.errors.CommError: It appears that you do not have permission to access the requested resource. Please reach out to the project owner to grant you access. If you have the correct permissions, verify that there are no issues with your networking setup.(Error 404: Not Found)
2024-03-07 01:00:09,169 DEBUG   HandlerThread:21404 [handler.py:handle_request():146] handle_request: shutdown
2024-03-07 01:00:09,169 INFO    HandlerThread:21404 [handler.py:finish():869] shutting down handler
2024-03-07 01:00:10,003 INFO    SenderThread:21404 [sender.py:finish():1572] shutting down sender
2024-03-07 01:00:10,140 INFO    WriterThread:21404 [datastore.py:close():296] close: /home/tho/SCRIMP/wandb/run-20240307_010008-8w7nwr8q/run-8w7nwr8q.wandb
